{
  "timestamp": "2025-09-01T15:45:29.237335",
  "summary": {
    "total": 5,
    "passed": 0,
    "failed": 5,
    "success_rate": 0.0
  },
  "results": {
    "bug_fixes": {
      "returncode": 1,
      "output": "/home/ubuntu/.local/lib/python3.10/site-packages/_pytest/config/__init__.py:331: PluggyTeardownRaisedWarning: A plugin raised an exception during an old-style hookwrapper teardown.\nPlugin: helpconfig, Hook: pytest_cmdline_parse\nImportError: cannot import name 'FixtureDef' from 'pytest' (/home/ubuntu/.local/lib/python3.10/site-packages/pytest/__init__.py)\nFor more information see https://pluggy.readthedocs.io/en/stable/api_reference.html#pluggy.PluggyTeardownRaisedWarning\n  config = pluginmanager.hook.pytest_cmdline_parse(\nTraceback (most recent call last):\n  File \"/usr/lib/python3.10/runpy.py\", line 196, in _run_module_as_main\n    return _run_code(code, main_globals, None,\n  File \"/usr/lib/python3.10/runpy.py\", line 86, in _run_code\n    exec(code, run_globals)\n  File \"/home/ubuntu/.local/lib/python3.10/site-packages/pytest/__main__.py\", line 5, in <module>\n    raise SystemExit(pytest.console_main())\n  File \"/home/ubuntu/.local/lib/python3.10/site-packages/_pytest/config/__init__.py\", line 192, in console_main\n    code = main()\n  File \"/home/ubuntu/.local/lib/python3.10/site-packages/_pytest/config/__init__.py\", line 150, in main\n    config = _prepareconfig(args, plugins)\n  File \"/home/ubuntu/.local/lib/python3.10/site-packages/_pytest/config/__init__.py\", line 331, in _prepareconfig\n    config = pluginmanager.hook.pytest_cmdline_parse(\n  File \"/home/ubuntu/.local/lib/python3.10/site-packages/pluggy/_hooks.py\", line 512, in __call__\n    return self._hookexec(self.name, self._hookimpls.copy(), kwargs, firstresult)\n  File \"/home/ubuntu/.local/lib/python3.10/site-packages/pluggy/_manager.py\", line 120, in _hookexec\n    return self._inner_hookexec(hook_name, methods, kwargs, firstresult)\n  File \"/home/ubuntu/.local/lib/python3.10/site-packages/pluggy/_callers.py\", line 167, in _multicall\n    raise exception\n  File \"/home/ubuntu/.local/lib/python3.10/site-packages/pluggy/_callers.py\", line 139, in _multicall\n    teardown.throw(exception)\n  File \"/home/ubuntu/.local/lib/python3.10/site-packages/pluggy/_callers.py\", line 43, in run_old_style_hookwrapper\n    teardown.send(result)\n  File \"/home/ubuntu/.local/lib/python3.10/site-packages/_pytest/helpconfig.py\", line 104, in pytest_cmdline_parse\n    config: Config = outcome.get_result()\n  File \"/home/ubuntu/.local/lib/python3.10/site-packages/pluggy/_result.py\", line 103, in get_result\n    raise exc.with_traceback(tb)\n  File \"/home/ubuntu/.local/lib/python3.10/site-packages/pluggy/_callers.py\", line 38, in run_old_style_hookwrapper\n    res = yield\n  File \"/home/ubuntu/.local/lib/python3.10/site-packages/pluggy/_callers.py\", line 121, in _multicall\n    res = hook_impl.function(*args)\n  File \"/home/ubuntu/.local/lib/python3.10/site-packages/_pytest/config/__init__.py\", line 1075, in pytest_cmdline_parse\n    self.parse(args)\n  File \"/home/ubuntu/.local/lib/python3.10/site-packages/_pytest/config/__init__.py\", line 1425, in parse\n    self._preparse(args, addopts=addopts)\n  File \"/home/ubuntu/.local/lib/python3.10/site-packages/_pytest/config/__init__.py\", line 1305, in _preparse\n    self.pluginmanager.load_setuptools_entrypoints(\"pytest11\")\n  File \"/home/ubuntu/.local/lib/python3.10/site-packages/pluggy/_manager.py\", line 416, in load_setuptools_entrypoints\n    plugin = ep.load()\n  File \"/usr/lib/python3.10/importlib/metadata/__init__.py\", line 171, in load\n    module = import_module(match.group('module'))\n  File \"/usr/lib/python3.10/importlib/__init__.py\", line 126, in import_module\n    return _bootstrap._gcd_import(name[level:], package, level)\n  File \"<frozen importlib._bootstrap>\", line 1050, in _gcd_import\n  File \"<frozen importlib._bootstrap>\", line 1027, in _find_and_load\n  File \"<frozen importlib._bootstrap>\", line 992, in _find_and_load_unlocked\n  File \"<frozen importlib._bootstrap>\", line 241, in _call_with_frames_removed\n  File \"<frozen importlib._bootstrap>\", line 1050, in _gcd_import\n  File \"<frozen importlib._bootstrap>\", line 1027, in _find_and_load\n  File \"<frozen importlib._bootstrap>\", line 1006, in _find_and_load_unlocked\n  File \"<frozen importlib._bootstrap>\", line 688, in _load_unlocked\n  File \"/home/ubuntu/.local/lib/python3.10/site-packages/_pytest/assertion/rewrite.py\", line 178, in exec_module\n    exec(co, module.__dict__)\n  File \"/home/ubuntu/unified-agent-server/general-agent/.venv/lib/python3.10/site-packages/pytest_asyncio/__init__.py\", line 6, in <module>\n    from .plugin import fixture, is_async_test\n  File \"/home/ubuntu/.local/lib/python3.10/site-packages/_pytest/assertion/rewrite.py\", line 178, in exec_module\n    exec(co, module.__dict__)\n  File \"/home/ubuntu/unified-agent-server/general-agent/.venv/lib/python3.10/site-packages/pytest_asyncio/plugin.py\", line 38, in <module>\n    from pytest import (\nImportError: cannot import name 'FixtureDef' from 'pytest' (/home/ubuntu/.local/lib/python3.10/site-packages/pytest/__init__.py)\n"
    },
    "views": {
      "returncode": 1,
      "output": "/home/ubuntu/.local/lib/python3.10/site-packages/_pytest/config/__init__.py:331: PluggyTeardownRaisedWarning: A plugin raised an exception during an old-style hookwrapper teardown.\nPlugin: helpconfig, Hook: pytest_cmdline_parse\nImportError: cannot import name 'FixtureDef' from 'pytest' (/home/ubuntu/.local/lib/python3.10/site-packages/pytest/__init__.py)\nFor more information see https://pluggy.readthedocs.io/en/stable/api_reference.html#pluggy.PluggyTeardownRaisedWarning\n  config = pluginmanager.hook.pytest_cmdline_parse(\nTraceback (most recent call last):\n  File \"/usr/lib/python3.10/runpy.py\", line 196, in _run_module_as_main\n    return _run_code(code, main_globals, None,\n  File \"/usr/lib/python3.10/runpy.py\", line 86, in _run_code\n    exec(code, run_globals)\n  File \"/home/ubuntu/.local/lib/python3.10/site-packages/pytest/__main__.py\", line 5, in <module>\n    raise SystemExit(pytest.console_main())\n  File \"/home/ubuntu/.local/lib/python3.10/site-packages/_pytest/config/__init__.py\", line 192, in console_main\n    code = main()\n  File \"/home/ubuntu/.local/lib/python3.10/site-packages/_pytest/config/__init__.py\", line 150, in main\n    config = _prepareconfig(args, plugins)\n  File \"/home/ubuntu/.local/lib/python3.10/site-packages/_pytest/config/__init__.py\", line 331, in _prepareconfig\n    config = pluginmanager.hook.pytest_cmdline_parse(\n  File \"/home/ubuntu/.local/lib/python3.10/site-packages/pluggy/_hooks.py\", line 512, in __call__\n    return self._hookexec(self.name, self._hookimpls.copy(), kwargs, firstresult)\n  File \"/home/ubuntu/.local/lib/python3.10/site-packages/pluggy/_manager.py\", line 120, in _hookexec\n    return self._inner_hookexec(hook_name, methods, kwargs, firstresult)\n  File \"/home/ubuntu/.local/lib/python3.10/site-packages/pluggy/_callers.py\", line 167, in _multicall\n    raise exception\n  File \"/home/ubuntu/.local/lib/python3.10/site-packages/pluggy/_callers.py\", line 139, in _multicall\n    teardown.throw(exception)\n  File \"/home/ubuntu/.local/lib/python3.10/site-packages/pluggy/_callers.py\", line 43, in run_old_style_hookwrapper\n    teardown.send(result)\n  File \"/home/ubuntu/.local/lib/python3.10/site-packages/_pytest/helpconfig.py\", line 104, in pytest_cmdline_parse\n    config: Config = outcome.get_result()\n  File \"/home/ubuntu/.local/lib/python3.10/site-packages/pluggy/_result.py\", line 103, in get_result\n    raise exc.with_traceback(tb)\n  File \"/home/ubuntu/.local/lib/python3.10/site-packages/pluggy/_callers.py\", line 38, in run_old_style_hookwrapper\n    res = yield\n  File \"/home/ubuntu/.local/lib/python3.10/site-packages/pluggy/_callers.py\", line 121, in _multicall\n    res = hook_impl.function(*args)\n  File \"/home/ubuntu/.local/lib/python3.10/site-packages/_pytest/config/__init__.py\", line 1075, in pytest_cmdline_parse\n    self.parse(args)\n  File \"/home/ubuntu/.local/lib/python3.10/site-packages/_pytest/config/__init__.py\", line 1425, in parse\n    self._preparse(args, addopts=addopts)\n  File \"/home/ubuntu/.local/lib/python3.10/site-packages/_pytest/config/__init__.py\", line 1305, in _preparse\n    self.pluginmanager.load_setuptools_entrypoints(\"pytest11\")\n  File \"/home/ubuntu/.local/lib/python3.10/site-packages/pluggy/_manager.py\", line 416, in load_setuptools_entrypoints\n    plugin = ep.load()\n  File \"/usr/lib/python3.10/importlib/metadata/__init__.py\", line 171, in load\n    module = import_module(match.group('module'))\n  File \"/usr/lib/python3.10/importlib/__init__.py\", line 126, in import_module\n    return _bootstrap._gcd_import(name[level:], package, level)\n  File \"<frozen importlib._bootstrap>\", line 1050, in _gcd_import\n  File \"<frozen importlib._bootstrap>\", line 1027, in _find_and_load\n  File \"<frozen importlib._bootstrap>\", line 992, in _find_and_load_unlocked\n  File \"<frozen importlib._bootstrap>\", line 241, in _call_with_frames_removed\n  File \"<frozen importlib._bootstrap>\", line 1050, in _gcd_import\n  File \"<frozen importlib._bootstrap>\", line 1027, in _find_and_load\n  File \"<frozen importlib._bootstrap>\", line 1006, in _find_and_load_unlocked\n  File \"<frozen importlib._bootstrap>\", line 688, in _load_unlocked\n  File \"/home/ubuntu/.local/lib/python3.10/site-packages/_pytest/assertion/rewrite.py\", line 178, in exec_module\n    exec(co, module.__dict__)\n  File \"/home/ubuntu/unified-agent-server/general-agent/.venv/lib/python3.10/site-packages/pytest_asyncio/__init__.py\", line 6, in <module>\n    from .plugin import fixture, is_async_test\n  File \"/home/ubuntu/.local/lib/python3.10/site-packages/_pytest/assertion/rewrite.py\", line 178, in exec_module\n    exec(co, module.__dict__)\n  File \"/home/ubuntu/unified-agent-server/general-agent/.venv/lib/python3.10/site-packages/pytest_asyncio/plugin.py\", line 38, in <module>\n    from pytest import (\nImportError: cannot import name 'FixtureDef' from 'pytest' (/home/ubuntu/.local/lib/python3.10/site-packages/pytest/__init__.py)\n"
    },
    "api": {
      "returncode": 1,
      "output": "/home/ubuntu/.local/lib/python3.10/site-packages/_pytest/config/__init__.py:331: PluggyTeardownRaisedWarning: A plugin raised an exception during an old-style hookwrapper teardown.\nPlugin: helpconfig, Hook: pytest_cmdline_parse\nImportError: cannot import name 'FixtureDef' from 'pytest' (/home/ubuntu/.local/lib/python3.10/site-packages/pytest/__init__.py)\nFor more information see https://pluggy.readthedocs.io/en/stable/api_reference.html#pluggy.PluggyTeardownRaisedWarning\n  config = pluginmanager.hook.pytest_cmdline_parse(\nTraceback (most recent call last):\n  File \"/usr/lib/python3.10/runpy.py\", line 196, in _run_module_as_main\n    return _run_code(code, main_globals, None,\n  File \"/usr/lib/python3.10/runpy.py\", line 86, in _run_code\n    exec(code, run_globals)\n  File \"/home/ubuntu/.local/lib/python3.10/site-packages/pytest/__main__.py\", line 5, in <module>\n    raise SystemExit(pytest.console_main())\n  File \"/home/ubuntu/.local/lib/python3.10/site-packages/_pytest/config/__init__.py\", line 192, in console_main\n    code = main()\n  File \"/home/ubuntu/.local/lib/python3.10/site-packages/_pytest/config/__init__.py\", line 150, in main\n    config = _prepareconfig(args, plugins)\n  File \"/home/ubuntu/.local/lib/python3.10/site-packages/_pytest/config/__init__.py\", line 331, in _prepareconfig\n    config = pluginmanager.hook.pytest_cmdline_parse(\n  File \"/home/ubuntu/.local/lib/python3.10/site-packages/pluggy/_hooks.py\", line 512, in __call__\n    return self._hookexec(self.name, self._hookimpls.copy(), kwargs, firstresult)\n  File \"/home/ubuntu/.local/lib/python3.10/site-packages/pluggy/_manager.py\", line 120, in _hookexec\n    return self._inner_hookexec(hook_name, methods, kwargs, firstresult)\n  File \"/home/ubuntu/.local/lib/python3.10/site-packages/pluggy/_callers.py\", line 167, in _multicall\n    raise exception\n  File \"/home/ubuntu/.local/lib/python3.10/site-packages/pluggy/_callers.py\", line 139, in _multicall\n    teardown.throw(exception)\n  File \"/home/ubuntu/.local/lib/python3.10/site-packages/pluggy/_callers.py\", line 43, in run_old_style_hookwrapper\n    teardown.send(result)\n  File \"/home/ubuntu/.local/lib/python3.10/site-packages/_pytest/helpconfig.py\", line 104, in pytest_cmdline_parse\n    config: Config = outcome.get_result()\n  File \"/home/ubuntu/.local/lib/python3.10/site-packages/pluggy/_result.py\", line 103, in get_result\n    raise exc.with_traceback(tb)\n  File \"/home/ubuntu/.local/lib/python3.10/site-packages/pluggy/_callers.py\", line 38, in run_old_style_hookwrapper\n    res = yield\n  File \"/home/ubuntu/.local/lib/python3.10/site-packages/pluggy/_callers.py\", line 121, in _multicall\n    res = hook_impl.function(*args)\n  File \"/home/ubuntu/.local/lib/python3.10/site-packages/_pytest/config/__init__.py\", line 1075, in pytest_cmdline_parse\n    self.parse(args)\n  File \"/home/ubuntu/.local/lib/python3.10/site-packages/_pytest/config/__init__.py\", line 1425, in parse\n    self._preparse(args, addopts=addopts)\n  File \"/home/ubuntu/.local/lib/python3.10/site-packages/_pytest/config/__init__.py\", line 1305, in _preparse\n    self.pluginmanager.load_setuptools_entrypoints(\"pytest11\")\n  File \"/home/ubuntu/.local/lib/python3.10/site-packages/pluggy/_manager.py\", line 416, in load_setuptools_entrypoints\n    plugin = ep.load()\n  File \"/usr/lib/python3.10/importlib/metadata/__init__.py\", line 171, in load\n    module = import_module(match.group('module'))\n  File \"/usr/lib/python3.10/importlib/__init__.py\", line 126, in import_module\n    return _bootstrap._gcd_import(name[level:], package, level)\n  File \"<frozen importlib._bootstrap>\", line 1050, in _gcd_import\n  File \"<frozen importlib._bootstrap>\", line 1027, in _find_and_load\n  File \"<frozen importlib._bootstrap>\", line 992, in _find_and_load_unlocked\n  File \"<frozen importlib._bootstrap>\", line 241, in _call_with_frames_removed\n  File \"<frozen importlib._bootstrap>\", line 1050, in _gcd_import\n  File \"<frozen importlib._bootstrap>\", line 1027, in _find_and_load\n  File \"<frozen importlib._bootstrap>\", line 1006, in _find_and_load_unlocked\n  File \"<frozen importlib._bootstrap>\", line 688, in _load_unlocked\n  File \"/home/ubuntu/.local/lib/python3.10/site-packages/_pytest/assertion/rewrite.py\", line 178, in exec_module\n    exec(co, module.__dict__)\n  File \"/home/ubuntu/unified-agent-server/general-agent/.venv/lib/python3.10/site-packages/pytest_asyncio/__init__.py\", line 6, in <module>\n    from .plugin import fixture, is_async_test\n  File \"/home/ubuntu/.local/lib/python3.10/site-packages/_pytest/assertion/rewrite.py\", line 178, in exec_module\n    exec(co, module.__dict__)\n  File \"/home/ubuntu/unified-agent-server/general-agent/.venv/lib/python3.10/site-packages/pytest_asyncio/plugin.py\", line 38, in <module>\n    from pytest import (\nImportError: cannot import name 'FixtureDef' from 'pytest' (/home/ubuntu/.local/lib/python3.10/site-packages/pytest/__init__.py)\n"
    },
    "edge_cases": {
      "returncode": 1,
      "output": "/home/ubuntu/.local/lib/python3.10/site-packages/_pytest/config/__init__.py:331: PluggyTeardownRaisedWarning: A plugin raised an exception during an old-style hookwrapper teardown.\nPlugin: helpconfig, Hook: pytest_cmdline_parse\nImportError: cannot import name 'FixtureDef' from 'pytest' (/home/ubuntu/.local/lib/python3.10/site-packages/pytest/__init__.py)\nFor more information see https://pluggy.readthedocs.io/en/stable/api_reference.html#pluggy.PluggyTeardownRaisedWarning\n  config = pluginmanager.hook.pytest_cmdline_parse(\nTraceback (most recent call last):\n  File \"/usr/lib/python3.10/runpy.py\", line 196, in _run_module_as_main\n    return _run_code(code, main_globals, None,\n  File \"/usr/lib/python3.10/runpy.py\", line 86, in _run_code\n    exec(code, run_globals)\n  File \"/home/ubuntu/.local/lib/python3.10/site-packages/pytest/__main__.py\", line 5, in <module>\n    raise SystemExit(pytest.console_main())\n  File \"/home/ubuntu/.local/lib/python3.10/site-packages/_pytest/config/__init__.py\", line 192, in console_main\n    code = main()\n  File \"/home/ubuntu/.local/lib/python3.10/site-packages/_pytest/config/__init__.py\", line 150, in main\n    config = _prepareconfig(args, plugins)\n  File \"/home/ubuntu/.local/lib/python3.10/site-packages/_pytest/config/__init__.py\", line 331, in _prepareconfig\n    config = pluginmanager.hook.pytest_cmdline_parse(\n  File \"/home/ubuntu/.local/lib/python3.10/site-packages/pluggy/_hooks.py\", line 512, in __call__\n    return self._hookexec(self.name, self._hookimpls.copy(), kwargs, firstresult)\n  File \"/home/ubuntu/.local/lib/python3.10/site-packages/pluggy/_manager.py\", line 120, in _hookexec\n    return self._inner_hookexec(hook_name, methods, kwargs, firstresult)\n  File \"/home/ubuntu/.local/lib/python3.10/site-packages/pluggy/_callers.py\", line 167, in _multicall\n    raise exception\n  File \"/home/ubuntu/.local/lib/python3.10/site-packages/pluggy/_callers.py\", line 139, in _multicall\n    teardown.throw(exception)\n  File \"/home/ubuntu/.local/lib/python3.10/site-packages/pluggy/_callers.py\", line 43, in run_old_style_hookwrapper\n    teardown.send(result)\n  File \"/home/ubuntu/.local/lib/python3.10/site-packages/_pytest/helpconfig.py\", line 104, in pytest_cmdline_parse\n    config: Config = outcome.get_result()\n  File \"/home/ubuntu/.local/lib/python3.10/site-packages/pluggy/_result.py\", line 103, in get_result\n    raise exc.with_traceback(tb)\n  File \"/home/ubuntu/.local/lib/python3.10/site-packages/pluggy/_callers.py\", line 38, in run_old_style_hookwrapper\n    res = yield\n  File \"/home/ubuntu/.local/lib/python3.10/site-packages/pluggy/_callers.py\", line 121, in _multicall\n    res = hook_impl.function(*args)\n  File \"/home/ubuntu/.local/lib/python3.10/site-packages/_pytest/config/__init__.py\", line 1075, in pytest_cmdline_parse\n    self.parse(args)\n  File \"/home/ubuntu/.local/lib/python3.10/site-packages/_pytest/config/__init__.py\", line 1425, in parse\n    self._preparse(args, addopts=addopts)\n  File \"/home/ubuntu/.local/lib/python3.10/site-packages/_pytest/config/__init__.py\", line 1305, in _preparse\n    self.pluginmanager.load_setuptools_entrypoints(\"pytest11\")\n  File \"/home/ubuntu/.local/lib/python3.10/site-packages/pluggy/_manager.py\", line 416, in load_setuptools_entrypoints\n    plugin = ep.load()\n  File \"/usr/lib/python3.10/importlib/metadata/__init__.py\", line 171, in load\n    module = import_module(match.group('module'))\n  File \"/usr/lib/python3.10/importlib/__init__.py\", line 126, in import_module\n    return _bootstrap._gcd_import(name[level:], package, level)\n  File \"<frozen importlib._bootstrap>\", line 1050, in _gcd_import\n  File \"<frozen importlib._bootstrap>\", line 1027, in _find_and_load\n  File \"<frozen importlib._bootstrap>\", line 992, in _find_and_load_unlocked\n  File \"<frozen importlib._bootstrap>\", line 241, in _call_with_frames_removed\n  File \"<frozen importlib._bootstrap>\", line 1050, in _gcd_import\n  File \"<frozen importlib._bootstrap>\", line 1027, in _find_and_load\n  File \"<frozen importlib._bootstrap>\", line 1006, in _find_and_load_unlocked\n  File \"<frozen importlib._bootstrap>\", line 688, in _load_unlocked\n  File \"/home/ubuntu/.local/lib/python3.10/site-packages/_pytest/assertion/rewrite.py\", line 178, in exec_module\n    exec(co, module.__dict__)\n  File \"/home/ubuntu/unified-agent-server/general-agent/.venv/lib/python3.10/site-packages/pytest_asyncio/__init__.py\", line 6, in <module>\n    from .plugin import fixture, is_async_test\n  File \"/home/ubuntu/.local/lib/python3.10/site-packages/_pytest/assertion/rewrite.py\", line 178, in exec_module\n    exec(co, module.__dict__)\n  File \"/home/ubuntu/unified-agent-server/general-agent/.venv/lib/python3.10/site-packages/pytest_asyncio/plugin.py\", line 38, in <module>\n    from pytest import (\nImportError: cannot import name 'FixtureDef' from 'pytest' (/home/ubuntu/.local/lib/python3.10/site-packages/pytest/__init__.py)\n"
    },
    "models": {
      "returncode": 1,
      "output": "/home/ubuntu/.local/lib/python3.10/site-packages/_pytest/config/__init__.py:331: PluggyTeardownRaisedWarning: A plugin raised an exception during an old-style hookwrapper teardown.\nPlugin: helpconfig, Hook: pytest_cmdline_parse\nImportError: cannot import name 'FixtureDef' from 'pytest' (/home/ubuntu/.local/lib/python3.10/site-packages/pytest/__init__.py)\nFor more information see https://pluggy.readthedocs.io/en/stable/api_reference.html#pluggy.PluggyTeardownRaisedWarning\n  config = pluginmanager.hook.pytest_cmdline_parse(\nTraceback (most recent call last):\n  File \"/usr/lib/python3.10/runpy.py\", line 196, in _run_module_as_main\n    return _run_code(code, main_globals, None,\n  File \"/usr/lib/python3.10/runpy.py\", line 86, in _run_code\n    exec(code, run_globals)\n  File \"/home/ubuntu/.local/lib/python3.10/site-packages/pytest/__main__.py\", line 5, in <module>\n    raise SystemExit(pytest.console_main())\n  File \"/home/ubuntu/.local/lib/python3.10/site-packages/_pytest/config/__init__.py\", line 192, in console_main\n    code = main()\n  File \"/home/ubuntu/.local/lib/python3.10/site-packages/_pytest/config/__init__.py\", line 150, in main\n    config = _prepareconfig(args, plugins)\n  File \"/home/ubuntu/.local/lib/python3.10/site-packages/_pytest/config/__init__.py\", line 331, in _prepareconfig\n    config = pluginmanager.hook.pytest_cmdline_parse(\n  File \"/home/ubuntu/.local/lib/python3.10/site-packages/pluggy/_hooks.py\", line 512, in __call__\n    return self._hookexec(self.name, self._hookimpls.copy(), kwargs, firstresult)\n  File \"/home/ubuntu/.local/lib/python3.10/site-packages/pluggy/_manager.py\", line 120, in _hookexec\n    return self._inner_hookexec(hook_name, methods, kwargs, firstresult)\n  File \"/home/ubuntu/.local/lib/python3.10/site-packages/pluggy/_callers.py\", line 167, in _multicall\n    raise exception\n  File \"/home/ubuntu/.local/lib/python3.10/site-packages/pluggy/_callers.py\", line 139, in _multicall\n    teardown.throw(exception)\n  File \"/home/ubuntu/.local/lib/python3.10/site-packages/pluggy/_callers.py\", line 43, in run_old_style_hookwrapper\n    teardown.send(result)\n  File \"/home/ubuntu/.local/lib/python3.10/site-packages/_pytest/helpconfig.py\", line 104, in pytest_cmdline_parse\n    config: Config = outcome.get_result()\n  File \"/home/ubuntu/.local/lib/python3.10/site-packages/pluggy/_result.py\", line 103, in get_result\n    raise exc.with_traceback(tb)\n  File \"/home/ubuntu/.local/lib/python3.10/site-packages/pluggy/_callers.py\", line 38, in run_old_style_hookwrapper\n    res = yield\n  File \"/home/ubuntu/.local/lib/python3.10/site-packages/pluggy/_callers.py\", line 121, in _multicall\n    res = hook_impl.function(*args)\n  File \"/home/ubuntu/.local/lib/python3.10/site-packages/_pytest/config/__init__.py\", line 1075, in pytest_cmdline_parse\n    self.parse(args)\n  File \"/home/ubuntu/.local/lib/python3.10/site-packages/_pytest/config/__init__.py\", line 1425, in parse\n    self._preparse(args, addopts=addopts)\n  File \"/home/ubuntu/.local/lib/python3.10/site-packages/_pytest/config/__init__.py\", line 1305, in _preparse\n    self.pluginmanager.load_setuptools_entrypoints(\"pytest11\")\n  File \"/home/ubuntu/.local/lib/python3.10/site-packages/pluggy/_manager.py\", line 416, in load_setuptools_entrypoints\n    plugin = ep.load()\n  File \"/usr/lib/python3.10/importlib/metadata/__init__.py\", line 171, in load\n    module = import_module(match.group('module'))\n  File \"/usr/lib/python3.10/importlib/__init__.py\", line 126, in import_module\n    return _bootstrap._gcd_import(name[level:], package, level)\n  File \"<frozen importlib._bootstrap>\", line 1050, in _gcd_import\n  File \"<frozen importlib._bootstrap>\", line 1027, in _find_and_load\n  File \"<frozen importlib._bootstrap>\", line 992, in _find_and_load_unlocked\n  File \"<frozen importlib._bootstrap>\", line 241, in _call_with_frames_removed\n  File \"<frozen importlib._bootstrap>\", line 1050, in _gcd_import\n  File \"<frozen importlib._bootstrap>\", line 1027, in _find_and_load\n  File \"<frozen importlib._bootstrap>\", line 1006, in _find_and_load_unlocked\n  File \"<frozen importlib._bootstrap>\", line 688, in _load_unlocked\n  File \"/home/ubuntu/.local/lib/python3.10/site-packages/_pytest/assertion/rewrite.py\", line 178, in exec_module\n    exec(co, module.__dict__)\n  File \"/home/ubuntu/unified-agent-server/general-agent/.venv/lib/python3.10/site-packages/pytest_asyncio/__init__.py\", line 6, in <module>\n    from .plugin import fixture, is_async_test\n  File \"/home/ubuntu/.local/lib/python3.10/site-packages/_pytest/assertion/rewrite.py\", line 178, in exec_module\n    exec(co, module.__dict__)\n  File \"/home/ubuntu/unified-agent-server/general-agent/.venv/lib/python3.10/site-packages/pytest_asyncio/plugin.py\", line 38, in <module>\n    from pytest import (\nImportError: cannot import name 'FixtureDef' from 'pytest' (/home/ubuntu/.local/lib/python3.10/site-packages/pytest/__init__.py)\n"
    }
  }
}